Workbook
Name __PN1: '[1]Upgrades pricing'!#REF!
Name __PN1: '[1]Upgrades pricing'!#REF!
Name _1.05gb_nonplug_drive: [2]Supplement2!#REF!
Name _1.05gb_nonplug_drive: [2]Supplement2!#REF!
Name _1.05gb_plug_drive: [2]Supplement2!#REF!
Name _1.05gb_plug_drive: [2]Supplement2!#REF!
Name _2.1gb_fastwide_plug_drive: [2]Supplement2!#REF!
Name _2.1gb_fastwide_plug_drive: [2]Supplement2!#REF!
Name _2.1gb_nonplug_drive: [2]Supplement2!#REF!
Name _2.1gb_nonplug_drive: [2]Supplement2!#REF!
Name _2.1gb_plug_drive: [2]Supplement2!#REF!
Name _2.1gb_plug_drive: [2]Supplement2!#REF!
Name _32mb_70nsmemory: [2]Supplement2!#REF!
Name _32mb_70nsmemory: [2]Supplement2!#REF!
Name _4.3gb_fastwide_plug_drive: [2]Supplement2!#REF!
Name _4.3gb_fastwide_plug_drive: [2]Supplement2!#REF!
Name _4.3gb_nonplug_drive: [2]Supplement2!#REF!
Name _4.3gb_nonplug_drive: [2]Supplement2!#REF!
Name _535mb_nonplug_drive: [2]Supplement2!#REF!
Name _535mb_nonplug_drive: [2]Supplement2!#REF!
Name _8mb_70nsmemory: [2]Supplement2!#REF!
Name _8mb_70nsmemory: [2]Supplement2!#REF!
Name _SMART_SCSIarray: [2]Supplement2!#REF!
Name _SMART_SCSIarray: [2]Supplement2!#REF!
Name _US1: #REF!
Name _US1: #REF!
Name Chart_1: "Chart 1"
Name COMPAQ_LIST: '[3]COMPAQ-LIST'!$A:$A
Name COMPAQ_RANGE: '[3]COMPAQ-LIST'!$A:$C
Name cost: #REF!
Name cost: #REF!
Name DazzlerPCI_array: [2]Supplement2!#REF!
Name DazzlerPCI_array: [2]Supplement2!#REF!
Name dfsa: [2]Supplement2!#REF!
Name dfsa: [2]Supplement2!#REF!
Name GM: #REF!
Name GM: #REF!
Name minus: #REF!
Name minus: #REF!
Name MODEL: #REF!
Name MODEL: #REF!
Name model2: #REF!
Name model2: #REF!
Name PL_storage: [2]Supplement2!#REF!
Name PL_storage: [2]Supplement2!#REF!
Name PN: '[1]Upgrades pricing'!#REF!
Name PN: '[1]Upgrades pricing'!#REF!
Name RANGE: #REF!
Name RANGE: #REF!
Name Scorpion_M2_processor: [2]Supplement2!#REF!
Name Scorpion_M2_processor: [2]Supplement2!#REF!
Name Seawolf_M2_processor: [2]Supplement2!#REF!
Name Seawolf_M2_processor: [2]Supplement2!#REF!
Name seawolf_TRadder: #REF!
Name seawolf_TRadder: #REF!
Name SM: '[4]model master'!$A$2:$A$65
Name SRP: #REF!
Name SRP: #REF!
Name Sturgeon_M2_processor: [2]Supplement2!#REF!
Name Sturgeon_M2_processor: [2]Supplement2!#REF!

Sheet 00.작성방법
B4: 1. 수익율과 방어율
C5: 수익율 = 프로젝트 계약금액 - 프로젝트 총 비용(내부 투입인력비 + 외주비 + 영업비 + 기타 프로젝트 완료에 사용된 비용일체)
C6: 방어율 = 예상된 수익율을 지켜내는 것(공식적인 용어는 아님)
B8: 2. PM과 원가관리
C9: PM은 프로젝트의 수익율을 지키기 위해(방어하기 위해) 일련의 관리활동을 함.
C10: 관리활동: 인력투입계획 수립, 예상되는 정기수익/지출계획 수립, 발생가능한 영업비 등 프로젝트 기간 내에 수익율에 영향을 끼지는 요인을 점검하는 것.
B12: 3. 수익율 산출
C13: 시기: (1차)견적서 작성 시, (2차)수행범위정의 시, (수시)프로젝트 진행 시 필요에 의해
C14: 수익율 기준: 기본 15% 이상으로 설정. 예외) 수익율에 관계없이 정책적인 필요에 의해 진행되는 경우.
B16: 4. 수익율 변경
C17: 견적 시 산출된 수익율은 WBS(수행범위)를 설계하면서 실제 투입공수가 변경됨으로 변경됨.(WBS(수행범위)는 계약금액의 근거가 됨)
B19: 5. 수익율관리 단계
C20: 원가계획 > 비용산정 > 비용할당 > 원가통제
B25: 1. 직접인건비 입력
B26: ①투입인원의 역할/성명/등급을 입력한다. 등급을 기입하면 등급에 따른 내부 일별 단가가 자동으로 나타난다.(내부 인력단가는 direct 탭을 참조)
B27: ②프로젝트 수행기간을 수정한다.(최초 월을 수정하면 최대 6개월까지 자동으로 가산된다)
B28: ③인력투입 계획란에 수행기간동안 투입할 월별 인력투입 공수를 입력한다(월 22일 기준이며, 일 공수 입력시 M/M와 일 단가가 자동 계산된다)
B29: ④익월에 전월에 실제 투입일을 입력한다.(월 22일 기준이며, 일 공수 입력시 M/M와 일 단가가 자동 계산된다)
B30: ⑤직접인건비 총 금액은 자동계산된다.
B32: 2. 직접경비 입력
B33: ①직접경비의 경비항목을 확인하고 월별로 예정된 직접경비를 입력한다.
B34: ②익월에 전월에 실제 사용된 직접경비를 입력한다.
B35: ③직접경비 총 금액은 자동계산된다.
B37: 3. 외주비
B38: ①외주비용이 지급되거나 외주가 예상될 경우 월별로 비용을 입력한다.
... B43: ②지출부문에는 앞서 입력한 직접인건비, 직접경비, 외주비가 자동입력되어 있고, 수익,수익율, 수익목표 월별성취율, 수익목표 월별 누적성취율도 자동입력되어 있다.

Sheet 01.견적내기
B2: ■00 견적내기
B4: 1. 직접인건비 | K4: 기준일 : | L4: 21
B5: 투입인원 | G5: 투입내역 | K5: 월별 투입일
G6: 계획 | I6: 실행 | K6: 43534 | M6: =K6+30 -> 43564 | O6: =M6+30 -> 43594 | Q6: =O6+30 -> 43624 | S6: =Q6+30 -> 43654 | U6: =S6+30 -> 43684 | W6: =U6+30 -> 43714 | Y6: =W6+30 -> 43744 | AA6: =Y6+30 -> 43774 | AC6: =AA6+30 -> 43804
B7: 구분 | C7: 역할 | D7: 성명 | E7: 등급 | F7: 기준금액 (일) | G7: MM | H7: 금액 | I7: MM | J7: 금액 | K7: 계획 | L7: 실행 | M7: 계획 | N7: 실행 | O7: 계획 | P7: 실행 | Q7: 계획 | R7: 실행 | S7: 계획 | T7: 실행 | U7: 계획 | V7: 실행 | W7: 계획 | X7: 실행 | Y7: 계획 | Z7: 실행 | AA7: 계획 | AB7: 실행 | AC7: 계획 | AD7: 실행
B8: 구축 | C8: PM | D8: 홍길동 | E8: 고급 | F8: =VLOOKUP(E8,'03.direct'!$B$4:$D$25,3,FALSE)/$L$4 -> 302524.1 | G8: =SUM(K8,M8,O8,Q8,S8,U8,AA8,AC8,W8,Y8)/L4 -> 0 | H8: =F8*G8*L4 -> 0 | I8: =SUM(L8,N8,P8,R8,T8,V8,AB8,AD8,X8,Z8)/L4 -> 0 | J8: =F8*I8*$L$4 -> 0
C9: 개발 | D9: 홍길남 | E9: 과장 | F9: =VLOOKUP(E9,'03.direct'!$B$4:$D$25,3,FALSE)/$L$4 -> 238095.24 | G9: =SUM(K9,M9,O9,Q9,S9,U9,AA9,AC9,W9,Y9)/L4 -> 0 | H9: =F9*G9*L4 -> 0 | I9: =SUM(L9,N9,P9,R9,T9,V9,AB9,AD9,X9,Z9)/L4 -> 0 | J9: =F9*I9*$L$4 -> 0
C10: 기획/디자인 | D10: 홍길서 | E10: 대리 | F10: =VLOOKUP(E10,'03.direct'!$B$4:$D$25,3,FALSE)/$L$4 -> 190476.19 | G10: =SUM(K10,M10,O10,Q10,S10,U10,AA10,AC10,W10,Y10)/L4 -> 0 | H10: =F10*G10*L4 -> 0 | I10: =SUM(L10,N10,P10,R10,T10,V10,AB10,AD10,X10,Z10)/L4 -> 0 | J10: =F10*I10*$L$4 -> 0
E11: PM | F11: =VLOOKUP(E11,'03.direct'!$B$4:$D$25,3,FALSE)/$L$4 -> 402948.48 | G11: =SUM(K11,M11,O11,Q11,S11,U11,AA11,AC11,W11,Y11)/L4 -> 0 | H11: =F11*G11*L4 -> 0 | I11: =SUM(L11,N11,P11,R11,T11,V11,AB11,AD11,X11,Z11)/L4 -> 0 | J11: =F11*I11*$L$4 -> 0
E12: UI/UX 디자이너 | F12: =VLOOKUP(E12,'03.direct'!$B$4:$D$25,3,FALSE)/$L$4 -> 226538.76 | G12: =SUM(K12,M12,O12,Q12,S12,U12,AA12,AC12,W12,Y12)/L4 -> 0 | H12: =F12*G12*L4 -> 0 | I12: =SUM(L12,N12,P12,R12,T12,V12,AB12,AD12,X12,Z12)/L4 -> 0 | J12: =F12*I12*$L$4 -> 0
E13: UI/UX 개발자 | F13: =VLOOKUP(E13,'03.direct'!$B$4:$D$25,3,FALSE)/$L$4 -> 271851.05 | G13: =SUM(K13,M13,O13,Q13,S13,U13,AA13,AC13,W13,Y13)/L4 -> 0 | H13: =F13*G13*L4 -> 0 | I13: =SUM(L13,N13,P13,R13,T13,V13,AB13,AD13,X13,Z13)/L4 -> 0 | J13: =F13*I13*$L$4 -> 0
F14: 계 | G14: =SUM(G8:G13) -> 0 | H14: =SUM(H8:H13) -> 0 | I14: =SUM(I8:I11) -> 0 | J14: =SUM(J8:J11) -> 0 | K14: =SUM(K8:K13) -> 0 | L14: =SUM(L8:L11) -> 0 | M14: =SUM(M8:M13) -> 0 | N14: =SUM(N8:N11) -> 0 | O14: =SUM(O8:O13) -> 0 | P14: =SUM(P8:P11) -> 0 | Q14: =SUM(Q8:Q13) -> 0 | R14: =SUM(R8:R11) -> 0 | S14: =SUM(S8:S13) -> 0 | T14: =SUM(T8:T11) -> 0 | U14: =SUM(U8:U13) -> 0 | V14: =SUM(V8:V11) -> 0 | W14: =SUM(W8:W11) -> 0 | X14: =SUM(X8:X11) -> 0 | Y14: =SUM(Y8:Y11) -> 0 | Z14: =SUM(Z8:Z11) -> 0 | AA14: =SUM(AA8:AA11) -> 0 | AB14: =SUM(AB8:AB11) -> 0 | AC14: =SUM(AC8:AC12) -> 0 | AD14: =SUM(AD8:AD11) -> 0
K15: =SUMPRODUCT((K8:K11)*($F8:$F11)) -> 0 | L15: =SUMPRODUCT((L8:L11)*($F8:$F11)) -> 0 | M15: =SUMPRODUCT((M8:M11)*($F8:$F11)) -> 0 | N15: =SUMPRODUCT((N8:N11)*($F8:$F11)) -> 0 | O15: =SUMPRODUCT((O8:O13)*($F8:$F13)) -> 0 | P15: =SUMPRODUCT((P8:P11)*($F8:$F11)) -> 0 | Q15: =SUMPRODUCT((Q8:Q13)*($F8:$F13)) -> 0 | R15: =SUMPRODUCT((R8:R11)*($F8:$F11)) -> 0 | S15: =SUMPRODUCT((S8:S13)*($F8:$F13)) -> 0 | T15: =SUMPRODUCT((T8:T11)*($F8:$F11)) -> 0 | U15: =SUMPRODUCT((U8:U13)*($F8:$F13)) -> 0 | V15: =SUMPRODUCT((V8:V11)*($F8:$F11)) -> 0 | W15: =SUMPRODUCT((W8:W11)*($F8:$F11)) -> 0 | X15: =SUMPRODUCT((X8:X11)*($F8:$F11)) -> 0 | Y15: =SUMPRODUCT((Y8:Y11)*($F8:$F11)) -> 0 | Z15: =SUMPRODUCT((Z8:Z11)*($F8:$F11)) -> 0 | AA15: =SUMPRODUCT((AA8:AA11)*($F8:$F11)) -> 0 | AB15: =SUMPRODUCT((AB8:AB11)*($F8:$F11)) -> 0 | AC15: =SUMPRODUCT((AC8:AC11)*($F8:$F11)) -> 0 | AD15: =SUMPRODUCT((AD8:AD11)*($F8:$F11)) -> 0
J16: =H14-J14 -> 0 | L16: =K15-L15 -> 0 | N16: =M15-N15 -> 0 | P16: =O15-P15 -> 0
B17: 2. 제경비(직접인건비, 외주비 외 기타경비) | O17: 계획과 실행을 맞바꿈
B18: 경비 항목 | G18: 경비 금액 | K18: 월별 투입일
K19: =K6 -> 43534 | M19: =K19+30 -> 43564 | O19: =M19+30 -> 43594 | Q19: =O19+30 -> 43624 | S19: =Q19+30 -> 43654 | U19: =S19+30 -> 43684 | W19: =U19+30 -> 43714 | Y19: =W19+30 -> 43744 | AA19: =Y19+30 -> 43774 | AC19: =AA19+30 -> 43804
B20: 구분 | C20: 항목 | E20: 상세내역 | H20: 계획 | J20: 실행 | K20: 계획 | L20: 실행 | M20: 계획 | N20: 실행 | O20: 계획 | P20: 실행 | Q20: 계획 | R20: 실행 | S20: 계획 | T20: 실행 | U20: 계획 | V20: 실행 | W20: 계획 | X20: 실행 | Y20: 계획 | Z20: 실행 | AA20: 계획 | AB20: 실행 | AC20: 계획 | AD20: 실행
B21: 복리후생비 | C21: 회식비(내부) | D21: 착수 시, 종료 시 | H21: =SUM(K21,M21,O21,Q21,S21,U21,AA21,AC21,W21,Y21) -> 0 | J21: =SUM(L21,N21,P21,R21,T21,V21,AB21,AD21,X21,Z21) -> 0
C22: 야식비 | D22: 1인당 1만원, 1주일에 3일 기준 | H22: =SUM(K22,M22,O22,Q22,S22,U22,AA22,AC22,W22,Y22) -> 0 | J22: =SUM(L22,N22,P22,R22,T22,V22,AB22,AD22,X22,Z22) -> 0
C23: 교통비 | D23: 야근 택시비 | H23: =SUM(K23,M23,O23,Q23,S23,U23,AA23,AC23,W23,Y23) -> 0 | J23: =SUM(L23,N23,P23,R23,T23,V23,AB23,AD23,X23,Z23) -> 0
C24: 기타 | D24: 기존 외부 플젝 시 복리후생비 월 120~130만원 발생 | H24: =SUM(K24,M24,O24,Q24,S24,U24,AA24,AC24,W24,Y24) -> 0 | J24: =SUM(L24,N24,P24,R24,T24,V24,AB24,AD24,X24,Z24) -> 0
C25: 계 | H25: =SUM(K25,M25,O25,Q25,S25,U25,AA25,AC25,W25,Y25) -> 0 | J25: =SUM(L25,N25,P25,R25,T25,V25,AB25,AD25,X25,Z25) -> 0 | K25: =SUM(K21:K24) -> 0 | L25: =SUM(L21:L24) -> 0 | M25: =SUM(M21:M24) -> 0 | N25: =SUM(N21:N24) -> 0 | O25: =SUM(O21:O24) -> 0 | P25: =SUM(P21:P24) -> 0 | Q25: =SUM(Q21:Q24) -> 0 | R25: =SUM(R21:R24) -> 0 | ... AD25: =SUM(AD21:AD24) -> 0
B26: 진행비 | C26: 고객접대 | D26: 컨소시엄 업체, 고객사 | H26: =SUM(K26,M26,O26,Q26,S26,U26,AA26,AC26,W26,Y26) -> 0 | J26: =SUM(L26,N26,P26,R26,T26,V26,AB26,AD26,X26,Z26) -> 0
C27: 보고서 작성비 | H27: =SUM(K27,M27,O27,Q27,S27,U27,AA27,AC27,W27,Y27) -> 0 | J27: =SUM(L27,N27,P27,R27,T27,V27,AB27,AD27,X27,Z27) -> 0
C28: 솔루션 | D28: 진단평가 솔루션(파수닷컴, 스패로우, 1개월) | H28: =SUM(K28,M28,O28,Q28,S28,U28,AA28,AC28,W28,Y28) -> 0 | J28: =SUM(L28,N28,P28,R28,T28,V28,AB28,AD28,X28,Z28) -> 0
C29: 계 | H29: =SUM(K29,M29,O29,Q29,S29,U29,AA29,AC29,W29,Y29) -> 0 | J29: =SUM(L29,N29,P29,R29,T29,V29,AB29,AD29,X29,Z29) -> 0 | K29: =SUM(K26:K28) -> 0 | L29: =SUM(L26:L28) -> 0 | M29: =SUM(M26:M28) -> 0 | N29: =SUM(N26:N28) -> 0 | O29: =SUM(O26:O28) -> 0 | P29: =SUM(P26:P28) -> 0 | Q29: =SUM(Q26:Q28) -> 0 | R29: =SUM(R26:R28) -> 0 | ... AD29: =SUM(AD26:AD28) -> 0
F30: 계 | H30: =SUM(H25,H29) -> 0 | I30: =SUM(I25,I29) -> 0 | J30: =SUM(J25,J29) -> 0 | K30: =SUM(K25,K29) -> 0 | L30: =SUM(L25,L29) -> 0 | M30: =SUM(M25,M29) -> 0 | N30: =SUM(N25,N29) -> 0 | O30: =SUM(O25,O29) -> 0 | ... AD30: =SUM(AD25,AD29) -> 0
B32: 3. 외주비
B33: 내용 | G33: 계 | K33: 월별 투입일
K34: =K6 -> 43534 | M34: =K34+30 -> 43564 | O34: =M34+30 -> 43594 | Q34: =O34+30 -> 43624 | S34: =Q34+30 -> 43654 | U34: =S34+30 -> 43684 | W34: =U34+30 -> 43714 | Y34: =W34+30 -> 43744 | AA34: =Y34+30 -> 43774 | AC34: =AA34+30 -> 43804
B35: 구분 | C35: 항목 | E35: 상세내역 | H35: 계획 | J35: 실행 | K35: 계획 | L35: 실행 | M35: 계획 | N35: 실행 | O35: 계획 | P35: 실행 | Q35: 계획 | R35: 실행 | S35: 계획 | T35: 실행 | U35: 계획 | V35: 실행 | W35: 계획 | X35: 실행 | Y35: 계획 | Z35: 실행 | AA35: 계획 | AB35: 실행 | AC35: 계획 | AD35: 실행
B36: 외주 | C36: 기획 | D36: 프리랜서 | E36: 고급 | H36: =SUM(K36,M36,O36,Q36,S36,U36,AA36,AC36,W36,Y36) -> 0 | J36: =SUM(L36,N36,P36,R36,T36,V36,AB36,AD36,X36,Z36) -> 0
C37: 개발 | D37: 프리랜서 | E37: 중급 | H37: =SUM(K37,M37,O37,Q37,S37,U37,AA37,AC37,W37,Y37) -> 0 | J37: =SUM(L37,N37,P37,R37,T37,V37,AB37,AD37,X37,Z37) -> 0
C38: 디자인 | D38: 업체 | E38: 턴키 | H38: =SUM(K38,M38,O38,Q38,S38,U38,AA38,AC38,W38,Y38) -> 0 | J38: =SUM(L38,N38,P38,R38,T38,V38,AB38,AD38,X38,Z38) -> 0
C39: 계 | H39: =SUM(K39,M39,O39,Q39,S39,U39,AA39,AC39,W39,Y39) -> 0 | J39: =SUM(L39,N39,P39,R39,T39,V39,AB39,AD39,X39,Z39) -> 0 | K39: =SUM(K36:K38) -> 0 | L39: =SUM(L36:L38) -> 0 | M39: =SUM(M36:M38) -> 0 | N39: =SUM(N36:N38) -> 0 | O39: =SUM(O36:O38) -> 0 | P39: =SUM(P36:P38) -> 0 | Q39: =SUM(Q36:Q38) -> 0 | R39: =SUM(R36:R38) -> 0 | ... AD39: =SUM(AD36:AD38) -> 0
F40: 계 | H40: =H39 -> 0 | I40: =I39 -> 0 | J40: =J39 -> 0 | K40: =K39 -> 0 | L40: =L39 -> 0 | M40: =M39 -> 0 | N40: =N39 -> 0 | O40: =O39 -> 0 | ... AD40: =AD39 -> 0
B42: 4. 수익현황(간접비 포함)
B43: 내용 | G43: 계 | K43: 월별 투입일
K44: =K6 -> 43534 | M44: =K44+30 -> 43564 | O44: =M44+30 -> 43594 | Q44: =O44+30 -> 43624 | S44: =Q44+30 -> 43654 | U44: =S44+30 -> 43684 | W44: =U44+30 -> 43714 | Y44: =W44+30 -> 43744 | AA44: =Y44+30 -> 43774 | AC44: =AA44+30 -> 43804
...

Sheet 03.direct
B1: 직접인건비 기준
B3: 등급(조정변수) | C3: 이름 | D3: 기준금액 (월) | F3: 2018년 적용 SW기술자 평균임금
B4: 특급 | D4: =K9 -> 8451914 | F4: 통계법 제27조(통계의 공표)에 따라 「2018년 SW기술자 임금실태조사(통계승인 제37501호)」의 SW기술자 평균임금을 공표합니다.
B5: 고급 | D5: =K10 -> 6353006 | L5: (단위 : 명, 원, %)
B6: 중급 | D6: =K11 -> 4986758 | F6: 구 분 | G6: 인원 | H6: 일평균임금(M/D) | K6: 월평균임금 | L6: 시간평균임금
B7: 초급 | D7: =K12 -> 4486165 | H7: 2017년 | I7: 2018년 | J7: (증가율) | K7: (M/M) | L7: (M/H)
B8: PM | D8: ='IT직무별 평균임금'!D14 -> 8461918 | F8: 기술사 | G8: 295 | H8: 452611 | I8: 462072 | J8: -2.1 | K8: 9611098 | L8: 57759
B9: UI/UX 개발자 | D9: ='IT직무별 평균임금'!D19 -> 5708872 | F9: 특급기술자 | G9: 15526 | H9: 391068 | I9: 406342 | J9: -3.9 | K9: 8451914 | L9: 50793
B10: UI/UX 디자이너 | D10: ='IT직무별 평균임금'!D20 -> 4757314 | F10: 고급기술자 | G10: 8742 | H10: 305353 | I10: 305433 | J10: 0 | K10: 6353006 | L10: 38179
F11: 중급기술자 | G11: 9104 | H11: 239506 | I11: 239748 | J11: -0.1 | K11: 4986758 | L11: 29969
F12: 초급기술자 | G12: 11363 | H12: 191320 | I12: 215681 | J12: -12.7 | K12: 4486165 | L12: 26960
F13: 고급기능사 | G13: 99 | H13: 191177 | I13: 194340 | J13: -1.7 | K13: 4042272 | L13: 24293
B14: 월평균 | D14: =SUM(D4:D13)/COUNTIF(D4:D13,">0") -> 6172278.1 | F14: 중급기능사 | G14: 200 | H14: 158490 | I14: 158597 | J14: -0.1 | K14: 3298818 | L14: 19825
F15: 초급기능사 | G15: 233 | H15: 114914 | I15: 120948 | J15: -5.3 | K15: 2515718 | L15: 15119
F16: 자료입력원 | G16: 204 | H16: 113959 | I16: 117145 | J16: -2.8 | K16: 2436616 | L16: 14643
B17: 직급(조정변수) | C17: 이음 | D17: 기준금액 (월) | F17: 계/평균 | G17: 45766 | H17: 289473 | I17: 302665 | J17: -4.6 | K17: 6295432 | L17: 37833
B18: 부장 | D18: 7000000
B19: 차장 | D19: 6000000 | F19: 21
B20: 과장 | D20: 5000000 | F20: =D18/F19 -> 333333.33
B21: 대리 | D21: 4000000
B22: 주임
B23: 사원

Sheet 04.indirect
B1: 간접비 기준
B3: 구분 | C3: 항목 | D3: 간접비율
B4: 직접인건비대비 | D4: 0.1
B5: 외주 | D5: 0
B13: ※ 1인당 월별로 발생하는 간접비 기준

Sheet ITSQF 직무체계 및 정의 (2)
A1: ITSQF 직무체계 및 정의
A3: 번호 | B3: ITSQF 직무 | C3: 조사용직무 | D3: 직무 정의
A4: 1 | B4: 정보기술기획 | C4: IT기획자 | D4: 조직의 경영목표를 달성하기 위하여 IT전략을 기획하고, 거버넌스, 투자성과분석, 운영 정책, R&D, 프로세스, 아키텍처 등 분야 별 전략을 수립하는 자이다.
A5: 2 | B5: 정보기술 컨설팅 | C5: IT컨설턴트 | D5: 조직의 목표를 달성하는데 도움이 될 수 있도록, 객관적인 시각에서 조직 경영 환경을 이해하고 대상 업무 및 정보시스템을 분석하여 개선 방안을 지도, 자문 및 상담을 수행하는 자이다.
A6: 3 | B6: 정보보호 컨설팅 | C6: 정보보호 컨설턴트 | D6: 주요 정보자산을 보호하기 위한 관리적, 물리적, 기술적 영역의 보안 요구사항과 사전 정의된 프로세스에 대해 객관적인 충족여부를 검증하고 자문하는 자이다.
A7: 4 | B7: 업무분석 | C7: 업무분석가 | D7: 조직의 비전과 목표, 구조, 정책 등의 이해를 바탕으로 업무 요구사항을 도출하고 분석*하여, 목적에 부합하는 대응전략 수립하는 자이다. * 타 직무에서 수행하는 분석, 설계 업무의 혼선 방지를 위해 아래의 주석을 표시함 1) 분석 : 조직 내·외부의 경영 환경에 영향을 주는 고객과 경쟁기업, 산업동향, 내부 역량을 분석하는 능력
A8: 5 | B8: 데이터분석 | C8: 데이터분석가 | D8: 데이터 이해 및 처리 기술에 대한 기본지식을 바탕으로 데이터 분석 기획, 데이터 분석, 데이터 시각화 업무를 수행하고 이를 통해 프로세스 혁신 및 마케팅 전략 결정 등의 과학적 의사결정을 지원하는 자이다.
A9: 6 | B9: IT프로젝트관리 | C9: IT PM | D9: IT프로젝트 인도물의 납기 준수를 위하여 프로젝트를 기획하고, 범위, 일정, 원가, 인적자원, 품질, 위험, 의사소통, 조달, 변경, 보안, 정보시스템 성과 등을 통합 관리하는 자이다.
A10: 7 | B10: IT프로젝트사업관리 | C10: IT PMO | D10: 명확한 의사결정과 방향 설정이 가능토록 지표를 제공하고 사업관리 지침 및 표준화 방안 제시, 주요이슈, 위험, 자원, 일정/문서, 범위관리를 통하여 프로젝트 수행을 지원하는 자이다.
A11: 8 | B11: SW아키텍처 | C11: SW 아키텍트 | D11: SW의 기능, 성능, 보안 등의 품질을 보장하고 SW를 구성하는 요소와 관계를 분석, 설계하여 전체적인 SW 구조를 체계화하는 자이다.
A12: 9 | B12: Infrastructure아키텍처 | C12: Infrastructure아키텍트 | D12: 하드웨어, 미들웨어, 네트워크, 클라우드를 포함하는 인프라를 설계, 구성하여 모든 지원들의 적합성 및 신뢰성 있는 서비스를 제공할 수 있도록 체계화하는 자이다.
A13: 10 | B13: 데이터아키텍처 | C13: 데이터 아키텍트 | D13: 데이터를 구조적 관점에서 설계, 생성, 배치, 관리하며, 다양한 데이터 엔터티뿐만 아니라 해당 데이터를 처리하는 애플리케이션에 의해 데이터가 저장, 소비, 통합 및 관리될 수 있도록 체계화하는 자이다.
A14: 11 | B14: UI/UX개발 | C14: UI/UX개발자 | D14: 사용자의 이용형태 및 기술환경을 분석하여, 사용자 인터페이스(UI/UX)의 기획 및 아키텍처를 구축하고, 프로토타입 검증, 설계 및 구현 과정을 통해 효과적인 UI/UX를 개발하는 자이다.
A15: 12 | B15: UI/UX디자인 | C15: UI/UX디자이너 | D15: UI/UX 디자인의 매체별 트렌드, 사용자 경험 분석을 통해 디자인 전략 및 콘셉트를 도출하고 UI 디자인 요소를 다양한 기법을 활용해 시각화하여 사용자 요구를 검증하고 매체별 최적화된 디자인과 사용성을 제공하는 자이다.
... A32: 29 | B32: IT기술교육 | C32: IT교육강사 | D32: IT분야의 기술교육을 체계적이고 효과적으로 수행하기 위하여 IT기술교육 방향 수립과 IT기술교육 환경조성, IT기술교육 교과개발 및 자료개발, IT기술교육 성과평가 등을 통해 성과 향상을 수행하는 일이다
A34: * ITSQF 참고자료 : https://www.sw.or.kr/site/sw/02/10204020000002017070310.jsp

Sheet (구)등급별 평균임금
A2: 2018년 적용 SW기술자 평균임금
A4: 통계법 제27조(통계의 공표)에 따라 「2018년 SW기술자 임금실태조사(통계승인 제37501호)」의 SW기술자 평균임금을 공표합니다.
A6: 【SW기술자 평균임금 - 등급별】
G8: (단위 : 명, 원, %)
A9: 구 분 | B9: 인원 | C9: 일평균임금(M/D) | F9: 월평균임금 | G9: 시간평균임금
C10: 2017년 | D10: 2018년 | E10: (증가율) | F10: (M/M) | G10: (M/H) | I10: 20.8
A11: 기술사 | B11: 295 | C11: 452611 | D11: 462072 | E11: -2.1 | F11: 9611098 | G11: 57759 | H11: =G11*8 -> 462072 | I11: =H11*I10 -> 9611097.6
A12: 특급기술자 | B12: 15526 | C12: 391068 | D12: 406342 | E12: -3.9 | F12: 8451914 | G12: 50793 | H12: =G12*8 -> 406344
A13: 고급기술자 | B13: 8742 | C13: 305353 | D13: 305433 | E13: 0 | F13: 6353006 | G13: 38179 | H13: =G13*8 -> 305432
A14: 중급기술자 | B14: 9104 | C14: 239506 | D14: 239748 | E14: -0.1 | F14: 4986758 | G14: 29969 | H14: =G14*8 -> 239752
A15: 초급기술자 | B15: 11363 | C15: 191320 | D15: 215681 | E15: -12.7 | F15: 4486165 | G15: 26960 | H15: =G15*8 -> 215680
A16: 고급기능사 | B16: 99 | C16: 191177 | D16: 194340 | E16: -1.7 | F16: 4042272 | G16: 24293 | H16: =G16*8 -> 194344
A17: 중급기능사 | B17: 200 | C17: 158490 | D17: 158597 | E17: -0.1 | F17: 3298818 | G17: 19825 | H17: =G17*8 -> 158600
A18: 초급기능사 | B18: 233 | C18: 114914 | D18: 120948 | E18: -5.3 | F18: 2515718 | G18: 15119 | H18: =G18*8 -> 120952
A19: 자료입력원 | B19: 204 | C19: 113959 | D19: 117145 | E19: -2.8 | F19: 2436616 | G19: 14643 | H19: =G19*8 -> 117144
A20: 계/평균 | B20: 45766 | C20: 289473 | D20: 302665 | E20: -4.6 | F20: 6295432 | G20: 37833
A22: <평균임금 SW사업대가 활용시 유의사항> ※ 본 조사결과는 SW사업에서 반드시 활용해야 하는 강제사항은 아님 ※ 등급별 평균임금은 2019년에는 공표하지 않고, IT직무별 평균임금을 공표할 예정임
A24: * SW기술자 평균임금은 소프트웨어산업진흥법 제22조(소프트웨어사업의 대가지급) 4항 ‘소프트웨어기술자의 노임단가’를 지칭함 * SW기술자 평균임금은 기본급, 제수당, 상여금, 퇴직급여충당금, 법인부담금을 모두 포함한 결과임 * 월평균임금은 일평균*근무일수(20.8일), 시간평균임금은 일평균÷8시간으로 각각 산정함 * 월평균 근무일수는 휴일, 법정공휴일 등을 제외한 업체의 응답된 근무일의 평균이며, 이는 개인의 휴가 사용여부와는 무관함 * SW기술자 평균임금은 2017년 대비 4.6% 증가함 * DB구축비 대가기준 가이드에서 활용되는 자료입력원 평균임금 내 기본급은 2018년 93,287원임
A26: [시행일] 2018년 9월 1일부터 2019년 8월 31일까지 적용
A28: 43341
A29: 한국소프트웨어산업협회장

Sheet IT직무별 평균임금
A2: 2022년 적용 SW기술자 평균 임금 공표
A4: 통계법 제27조(통계의 공표)에 따라 『2022년 적용 SW기술자 임금실태조사 (통계승인 제375001호)』의 SW기술자 평균임금을 공표합니다.
A6: 【SW기술자 평균임금】
E7: (단위: 원)
B8: 구 분 | C8: 일평균 임금 | D8: 월평균 임금 | E8: 시간평균 임금
B9: 1. IT기획자 | C9: 360307 | D9: 7494386 | E9: 45038
B10: 2. IT컨설턴트 | C10: 484732 | D10: 10082426 | E10: 60592
B11: 3. 정보보호컨설턴트 | C11: 347123 | D11: 7220158 | E11: 43390
B12: 4. 업무분석가 | C12: 548550 | D12: 11409840 | E12: 68569
B13: 5. 데이터분석가 | C13: 323184 | D13: 6722227 | E13: 40398
B14: 6. IT PM | C14: 406823 | D14: 8461918 | E14: 50853
B15: 7. IT PMO | C15: 345428 | D15: 7184902 | E15: 43179
B16: 8. SW 아키텍트 | C16: 448240 | D16: 9323392 | E16: 56030
B17: 9. Infrastructure아키텍트 | C17: 556512 | D17: 11575450 | E17: 69564
B18: 10. 데이터 아키텍트 | C18: 414770 | D18: 8627216 | E18: 51846
B19: 11. UI/UX 개발자 | C19: 274465 | D19: 5708872 | E19: 34308
B20: 12. UI/UX 디자이너 | C20: 228717 | D20: 4757314 | E20: 28590
... B37: 29 IT교육강사 | C37: 279165 | D37: 5806632 | E37: 34896
B39: <본 평균임금을 SW사업대가 활용시 유의사항> ※ 본 조사결과는 SW사업에서 SW기술자 인건비로 참고 활용 가능하며, 수‧발주자간 자율적 협의에 의해 적용할 수 있음 * SW기술자 평균임금은 소프트웨어진흥법 제46조(적정대가지급등) 제4항 ‘소프트웨어기술자의 인건비 기준’을 지칭함 * SW기술자 평균임금은 기본급, 제수당, 상여금, 퇴직급여충당금, 법인부담금을 모두 포함한 결과임 * 일평균임금은 월평균÷근무일수(20.8일), 시간평균임금은 일평균÷8시간으로 각각 산정함 * 월평균 근무일수는 휴일, 법정공휴일 등을 제외한 업체가 응답한 근무일의 평균이며, 이는 개인의 휴가 사용여부와는 무관함 * SW기술자 전체 평균임금은 전년대비 2.6% 증가 - 2020년 공표된 평균임금을 변경된 임금추정방식(가중평균)으로 환산하여 비교 * IT직무 중 26. IT감사, 29.IT교육강사는 유효응답(30명 이상) 표본이 적어 활용시 유의해야함
B41: [시행일] 2022년 1월 10일부터 2022년 12월 31일까지 적용
A43: 44571
A44: 한국소프트웨어산업협회장

Sheet IT직무별 상하위 구간 평균임금
A1: 2022년 적용 SW기술자 임금실태조사 _ 사분위 값
D3: (단위: 원)
A4: 구 분 | B4: 75백분위수 | C4: 25백분위수 | D4: 전체 평균임금
B5: (일평균 임금) | C5: (일평균 임금) | D5: (일평균 임금)
A6: 1. IT기획자 | B6: 396436 | C6: 213176 | D6: 360307
A7: 2. IT컨설턴트 | B7: 533584 | C7: 278295 | D7: 484732
A8: 3. 정보보호컨설턴트 | B8: 415612 | C8: 214662 | D8: 347123
A9: 4. 업무분석가 | B9: 658422 | C9: 423003 | D9: 548550
A10: 5. 데이터분석가 | B10: 361287 | C10: 239965 | D10: 323184
A11: 6. IT PM | B11: 481456 | C11: 277463 | D11: 406823
A12: 7. IT PMO | B12: 404213 | C12: 216417 | D12: 345428
A13: 8. SW 아키텍트 | B13: 458653 | C13: 280367 | D13: 448240
A14: 9. Infrastructure아키텍트 | B14: 736903 | C14: 430266 | D14: 556512
A15: 10. 데이터 아키텍트 | B15: 475950 | C15: 263152 | D15: 414770
A16: 11. UI/UX 개발자 | B16: 323971 | C16: 155597 | D16: 274465
A17: 12. UI/UX 디자이너 | B17: 286449 | C17: 148097 | D17: 228717
... A34: 29 IT교육강사 | B34: 333740 | C34: 208606 | D34: 279165

Sheet ITSQF 직무체계 및 정의
A1: ITSQF 직무체계 및 정의
A3: 번호 | B3: ITSQF 직무 | C3: 조사용직무 | D3: 직무 정의
A4: 1 | B4: 정보기술기획 | C4: IT기획자 | D4: 조직의 경영목표를 달성하기 위하여 IT전략을 기획하고, 거버넌스, 투자성과분석, 운영 정책, R&D, 프로세스, 아키텍처 등 분야 별 전략을 수립하는 자이다.
A5: 2 | B5: 정보기술 컨설팅 | C5: IT컨설턴트 | D5: 조직의 목표를 달성하는데 도움이 될 수 있도록, 객관적인 시각에서 조직 경영 환경을 이해하고 대상 업무 및 정보시스템을 분석하여 개선 방안을 지도, 자문 및 상담을 수행하는 자이다.
A6: 3 | B6: 정보보호 컨설팅 | C6: 정보보호 컨설턴트 | D6: 주요 정보자산을 보호하기 위한 관리적, 물리적, 기술적 영역의 보안 요구사항과 사전 정의된 프로세스에 대해 객관적인 충족여부를 검증하고 자문하는 자이다.
A7: 4 | B7: 업무분석 | C7: 업무분석가 | D7: 조직의 비전과 목표, 구조, 정책 등의 이해를 바탕으로 업무 요구사항을 도출하고 분석*하여, 목적에 부합하는 대응전략 수립하는 자이다. * 타 직무에서 수행하는 분석, 설계 업무의 혼선 방지를 위해 아래의 주석을 표시함 1) 분석 : 조직 내·외부의 경영 환경에 영향을 주는 고객과 경쟁기업, 산업동향, 내부 역량을 분석하는 능력
A8: 5 | B8: 데이터분석 | C8: 데이터분석가 | D8: 데이터 이해 및 처리 기술에 대한 기본지식을 바탕으로 데이터 분석 기획, 데이터 분석, 데이터 시각화 업무를 수행하고 이를 통해 프로세스 혁신 및 마케팅 전략 결정 등의 과학적 의사결정을 지원하는 자이다.
A9: 6 | B9: IT프로젝트관리 | C9: IT PM | D9: IT프로젝트 인도물의 납기 준수를 위하여 프로젝트를 기획하고, 범위, 일정, 원가, 인적자원, 품질, 위험, 의사소통, 조달, 변경, 보안, 정보시스템 성과 등을 통합 관리하는 자이다.
A10: 7 | B10: IT프로젝트사업관리 | C10: IT PMO | D10: 명확한 의사결정과 방향 설정이 가능토록 지표를 제공하고 사업관리 지침 및 표준화 방안 제시, 주요이슈, 위험, 자원, 일정/문서, 범위관리를 통하여 프로젝트 수행을 지원하는 자이다.
A11: 8 | B11: SW아키텍처 | C11: SW 아키텍트 | D11: SW의 기능, 성능, 보안 등의 품질을 보장하고 SW를 구성하는 요소와 관계를 분석, 설계하여 전체적인 SW 구조를 체계화하는 자이다.
A12: 9 | B12: Infrastructure아키텍처 | C12: Infrastructure아키텍트 | D12: 하드웨어, 미들웨어, 네트워크, 클라우드를 포함하는 인프라를 설계, 구성하여 모든 지원들의 적합성 및 신뢰성 있는 서비스를 제공할 수 있도록 체계화하는 자이다.
A13: 10 | B13: 데이터아키텍처 | C13: 데이터 아키텍트 | D13: 데이터를 구조적 관점에서 설계, 생성, 배치, 관리하며, 다양한 데이터 엔터티뿐만 아니라 해당 데이터를 처리하는 애플리케이션에 의해 데이터가 저장, 소비, 통합 및 관리될 수 있도록 체계화하는 자이다.
A14: 11 | B14: UI/UX개발 | C14: UI/UX개발자 | D14: 사용자의 이용형태 및 기술환경을 분석하여, 사용자 인터페이스(UI/UX)의 기획 및 아키텍처를 구축하고, 프로토타입 검증, 설계 및 구현 과정을 통해 효과적인 UI/UX를 개발하는 자이다.
A15: 12 | B15: UI/UX디자인 | C15: UI/UX디자이너 | D15: UI/UX 디자인의 매체별 트렌드, 사용자 경험 분석을 통해 디자인 전략 및 콘셉트를 도출하고 UI 디자인 요소를 다양한 기법을 활용해 시각화하여 사용자 요구를 검증하고 매체별 최적화된 디자인과 사용성을 제공하는 자이다.
... A32: 29 | B32: IT기술교육 | C32: IT교육강사 | D32: IT분야의 기술교육을 체계적이고 효과적으로 수행하기 위하여 IT기술교육 방향 수립과 IT기술교육 환경조성, IT기술교육 교과개발 및 자료개발, IT기술교육 성과평가 등을 통해 성과 향상을 수행하는 일이다
A34: * ITSQF 참고자료 : https://www.sw.or.kr/site/sw/02/10204020000002017070310.jsp

Sheet (구)등급 분류기준
A1: SW기술자 등급제는 2012년 SW산업진흥법에서 폐지되었습니다. 아래의 기준은 등급제 폐지 이전의 등급분류 기준임을 참고하시기 바랍니다.

Sheet SW기술자범위
A1: ※ “소프트웨어 기술자”의 범위는 소프트웨어산업진흥법 제2조 5호에서 정한 바에 따름 소프트웨어산업 진흥법 제2조(정의) ⑤ "소프트웨어기술자"란 「국가기술자격법」에 따라 정보처리 분야의 기술자격을 취득한 사람 또는 소프트웨어 기술 분야에서 대통령령으로 정하는 학력이나 경력을 가진 사람을 말한다. 소프트웨어산업 진흥법 시행령 제1조의2(소프트웨어기술자의 범위) ① 「소프트웨어산업 진흥법」(이하 "법"이라 한다) 제2조제5호에서 "대통령령으로 정하는 학력이나 경력을 가진 사람"이란 다음 각 호의 어느 하나에 해당하는 사람을 말한다. 1. 「초·중등교육법」 제2조제3호 또는 「고등교육법」 제2조에 따른 각급 학교에서 소프트웨어 기술 분야를 전공한 사람 2. 소프트웨어 기술을 가진 사람으로서 소프트웨어 기술 분야에서 일정 기간 경력을 갖추거나 근무한 사람 3. 그 밖에 제1호 및 제2호에 따른 기준과 같거나 그 이상의 학력 또는 경력이 있다고 인정되는 사람 ② 제1항에 따른 소프트웨어기술자에 대한 세부적인 인정 기준 및 절차·방법 등은 과학기술정보통신부장관이 정하여 고시한다
